Workbook

Sheet Overview
A1: EcoLoop execution harness
A2: As of 15 October 2026 · Collaborative planning · No application implementation claimed
A3: Update Tasks inputs; phase progress counts leaf units and gates once.
A5: Phase | B5: Outcome | C5: Horizon | D5: Units | E5: Verified | F5: Progress | G5: In progress | H5: Dependency open | I5: Phase gate
A6: P00 | B6: Planning and scope approval | C6: Planning | D6: =COUNTIFS(Tasks!$B$6:$B$161,A6) -> 13 | E6: =COUNTIFS(Tasks!$B$6:$B$161,A6,Tasks!$H$6:$H$161,"Verified") -> 0 | F6: =IF(D6=0,"No units",E6/D6) -> 0 | G6: =COUNTIFS(Tasks!$B$6:$B$161,A6,Tasks!$F$6:$F$161,"In progress") -> 0 | H6: =COUNTIFS(Tasks!$B$6:$B$161,A6,Tasks!$H$6:$H$161,"Dependency open") -> 10 | I6: =VLOOKUP(A6&".90.01",Tasks!$A$6:$H$161,8,FALSE) -> Dependency open
A7: P01 | B7: Trusted foundation and contracts | C7: Demo | D7: =COUNTIFS(Tasks!$B$6:$B$161,A7) -> 13 | E7: =COUNTIFS(Tasks!$B$6:$B$161,A7,Tasks!$H$6:$H$161,"Verified") -> 0 | F7: =IF(D7=0,"No units",E7/D7) -> 0 | G7: =COUNTIFS(Tasks!$B$6:$B$161,A7,Tasks!$F$6:$F$161,"In progress") -> 0 | H7: =COUNTIFS(Tasks!$B$6:$B$161,A7,Tasks!$H$6:$H$161,"Dependency open") -> 13 | I7: =VLOOKUP(A7&".90.01",Tasks!$A$6:$H$161,8,FALSE) -> Dependency open
A8: P02 | B8: Deterministic baseline and synthetic household flow | C8: Demo | D8: =COUNTIFS(Tasks!$B$6:$B$161,A8) -> 13 | E8: =COUNTIFS(Tasks!$B$6:$B$161,A8,Tasks!$H$6:$H$161,"Verified") -> 0 | F8: =IF(D8=0,"No units",E8/D8) -> 0 | G8: =COUNTIFS(Tasks!$B$6:$B$161,A8,Tasks!$F$6:$F$161,"In progress") -> 0 | H8: =COUNTIFS(Tasks!$B$6:$B$161,A8,Tasks!$H$6:$H$161,"Dependency open") -> 13 | I8: =VLOOKUP(A8&".90.01",Tasks!$A$6:$H$161,8,FALSE) -> Dependency open
A9: P03 | B9: Gemini intake and single-orchestrator household journey | C9: Demo | D9: =COUNTIFS(Tasks!$B$6:$B$161,A9) -> 13 | E9: =COUNTIFS(Tasks!$B$6:$B$161,A9,Tasks!$H$6:$H$161,"Verified") -> 0 | F9: =IF(D9=0,"No units",E9/D9) -> 0 | G9: =COUNTIFS(Tasks!$B$6:$B$161,A9,Tasks!$F$6:$F$161,"In progress") -> 0 | H9: =COUNTIFS(Tasks!$B$6:$B$161,A9,Tasks!$H$6:$H$161,"Dependency open") -> 13 | I9: =VLOOKUP(A9&".90.01",Tasks!$A$6:$H$161,8,FALSE) -> Dependency open
A10: P04 | B10: Google deployment and submission readiness | C10: Demo | D10: =COUNTIFS(Tasks!$B$6:$B$161,A10) -> 13 | E10: =COUNTIFS(Tasks!$B$6:$B$161,A10,Tasks!$H$6:$H$161,"Verified") -> 0 | F10: =IF(D10=0,"No units",E10/D10) -> 0 | G10: =COUNTIFS(Tasks!$B$6:$B$161,A10,Tasks!$F$6:$F$161,"In progress") -> 0 | H10: =COUNTIFS(Tasks!$B$6:$B$161,A10,Tasks!$H$6:$H$161,"Dependency open") -> 13 | I10: =VLOOKUP(A10&".90.01",Tasks!$A$6:$H$161,8,FALSE) -> Dependency open
A11: P05 | B11: Institutional kitchen extension | C11: Expansion | D11: =COUNTIFS(Tasks!$B$6:$B$161,A11) -> 13 | E11: =COUNTIFS(Tasks!$B$6:$B$161,A11,Tasks!$H$6:$H$161,"Verified") -> 0 | F11: =IF(D11=0,"No units",E11/D11) -> 0 | G11: =COUNTIFS(Tasks!$B$6:$B$161,A11,Tasks!$F$6:$F$161,"In progress") -> 0 | H11: =COUNTIFS(Tasks!$B$6:$B$161,A11,Tasks!$H$6:$H$161,"Dependency open") -> 13 | I11: =VLOOKUP(A11&".90.01",Tasks!$A$6:$H$161,8,FALSE) -> Dependency open
A12: P06 | B12: Qualified recovery coordination | C12: Expansion | D12: =COUNTIFS(Tasks!$B$6:$B$161,A12) -> 13 | E12: =COUNTIFS(Tasks!$B$6:$B$161,A12,Tasks!$H$6:$H$161,"Verified") -> 0 | F12: =IF(D12=0,"No units",E12/D12) -> 0 | G12: =COUNTIFS(Tasks!$B$6:$B$161,A12,Tasks!$F$6:$F$161,"In progress") -> 0 | H12: =COUNTIFS(Tasks!$B$6:$B$161,A12,Tasks!$H$6:$H$161,"Dependency open") -> 13 | I12: =VLOOKUP(A12&".90.01",Tasks!$A$6:$H$161,8,FALSE) -> Dependency open
A13: P07 | B13: Organics and processor evidence | C13: Expansion | D13: =COUNTIFS(Tasks!$B$6:$B$161,A13) -> 13 | E13: =COUNTIFS(Tasks!$B$6:$B$161,A13,Tasks!$H$6:$H$161,"Verified") -> 0 | F13: =IF(D13=0,"No units",E13/D13) -> 0 | G13: =COUNTIFS(Tasks!$B$6:$B$161,A13,Tasks!$F$6:$F$161,"In progress") -> 0 | H13: =COUNTIFS(Tasks!$B$6:$B$161,A13,Tasks!$H$6:$H$161,"Dependency open") -> 13 | I13: =VLOOKUP(A13&".90.01",Tasks!$A$6:$H$161,8,FALSE) -> Dependency open
A14: P08 | B14: Permissioned pilot and operating model | C14: Pilot | D14: =COUNTIFS(Tasks!$B$6:$B$161,A14) -> 13 | E14: =COUNTIFS(Tasks!$B$6:$B$161,A14,Tasks!$H$6:$H$161,"Verified") -> 0 | F14: =IF(D14=0,"No units",E14/D14) -> 0 | G14: =COUNTIFS(Tasks!$B$6:$B$161,A14,Tasks!$F$6:$F$161,"In progress") -> 0 | H14: =COUNTIFS(Tasks!$B$6:$B$161,A14,Tasks!$H$6:$H$161,"Dependency open") -> 13 | I14: =VLOOKUP(A14&".90.01",Tasks!$A$6:$H$161,8,FALSE) -> Dependency open
A15: P09 | B15: Repair reuse and material exchange discovery | C15: Expansion | D15: =COUNTIFS(Tasks!$B$6:$B$161,A15) -> 13 | E15: =COUNTIFS(Tasks!$B$6:$B$161,A15,Tasks!$H$6:$H$161,"Verified") -> 0 | F15: =IF(D15=0,"No units",E15/D15) -> 0 | G15: =COUNTIFS(Tasks!$B$6:$B$161,A15,Tasks!$F$6:$F$161,"In progress") -> 0 | H15: =COUNTIFS(Tasks!$B$6:$B$161,A15,Tasks!$H$6:$H$161,"Dependency open") -> 13 | I15: =VLOOKUP(A15&".90.01",Tasks!$A$6:$H$161,8,FALSE) -> Dependency open
A16: P10 | B16: Energy and water modules discovery | C16: Expansion | D16: =COUNTIFS(Tasks!$B$6:$B$161,A16) -> 13 | E16: =COUNTIFS(Tasks!$B$6:$B$161,A16,Tasks!$H$6:$H$161,"Verified") -> 0 | F16: =IF(D16=0,"No units",E16/D16) -> 0 | G16: =COUNTIFS(Tasks!$B$6:$B$161,A16,Tasks!$F$6:$F$161,"In progress") -> 0 | H16: =COUNTIFS(Tasks!$B$6:$B$161,A16,Tasks!$H$6:$H$161,"Dependency open") -> 13 | I16: =VLOOKUP(A16&".90.01",Tasks!$A$6:$H$161,8,FALSE) -> Dependency open
A17: P11 | B17: Ecosystem scale and commercial reliability | C17: Scale | D17: =COUNTIFS(Tasks!$B$6:$B$161,A17) -> 13 | E17: =COUNTIFS(Tasks!$B$6:$B$161,A17,Tasks!$H$6:$H$161,"Verified") -> 0 | F17: =IF(D17=0,"No units",E17/D17) -> 0 | G17: =COUNTIFS(Tasks!$B$6:$B$161,A17,Tasks!$F$6:$F$161,"In progress") -> 0 | H17: =COUNTIFS(Tasks!$B$6:$B$161,A17,Tasks!$H$6:$H$161,"Dependency open") -> 13 | I17: =VLOOKUP(A17&".90.01",Tasks!$A$6:$H$161,8,FALSE) -> Dependency open
A20: Total planned units | B20: =COUNTA(Tasks!$A$6:$A$161) -> 156
A21: Verified units | B21: =COUNTIFS(Tasks!$H$6:$H$161,"Verified") -> 0
A22: Demo gate | B22: =VLOOKUP("P04.90.01",Tasks!$A$6:$H$161,8,FALSE) -> Dependency open
A25: Blueprint folder | B25: https://drive.google.com/drive/folders/1mhYQLzTWc1uwqF9BkkkIy44y7R6GikpC
A26: Control room link | B26: Added after document publication
A29: Formula verification cannot establish that evidence is truthful; accountable review remains required.

Sheet Tasks
A1: EcoLoop tasks — live completion and evidence
A2: Use filters; preserve row order. Checked boxes need evidence, reviewer, date and verified prerequisites.
A3: Initial state: proposed tasks only. Owner roles are placeholders; coding is not authorized by this documentation request.
A5: Unit ID | B5: Phase | C5: Parent task | D5: Granular unit | E5: Owner | F5: Status | G5: Done | H5: Calculated result | I5: Evidence link | J5: Reviewer | K5: Updated (ISO) | L5: Prerequisite 1 | M5: Prerequisite 2 | N5: Prerequisite 3 | O5: Dependency readiness | P5: Acceptance condition | Q5: Expected evidence | R5: Estimate hours | S5: Context tokens | T5: Requirement / journey | U5: Blocker / notes | V5: Horizon
A6: P00.01.01 | B6: P00 | C6: P00.01 Product and evidence | D6: Review source inventory and conflicts | E6: Product owner | F6: Not started | G6: FALSE | H6: =IF(COUNTIFS($A$6:$A$161,A6)<>1,"Duplicate ID",IF(O6<>"Ready","Dependency open",IF(G6=TRUE,IF(AND(F6="Complete",I6<>"",J6<>"",K6<>""),"Verified","Evidence required"),IF(F6="Complete","Check completion",IF(F6="Blocked","Blocked",IF(F6="In progress","In progress",IF(F6="In review","In review","Open"))))))) -> Open | O6: ="Ready" -> Ready | P6: Coverage and contradiction register acknowledged; source gaps have owners | Q6: Research inventory + product source review | S6: 6000 | T6: REQ-SCOPE-01 | U6: Proposed work; implementation not authorized by this documentation request. | V6: Planning
A7: P00.01.02 | B7: P00 | C7: P00.01 Product and evidence | D7: Select initial actor and decision window | E7: Product owner | F7: Not started | G7: FALSE | H7: =IF(COUNTIFS($A$6:$A$161,A7)<>1,"Duplicate ID",IF(O7<>"Ready","Dependency open",IF(G7=TRUE,IF(AND(F7="Complete",I7<>"",J7<>"",K7<>""),"Verified","Evidence required"),IF(F7="Complete","Check completion",IF(F7="Blocked","Blocked",IF(F7="In progress","In progress",IF(F7="In review","In review","Open"))))))) -> Dependency open | L7: P00.01.01 | O7: =IF(AND(OR(L7="",IFNA(VLOOKUP(L7,$A$6:$H$6,8,FALSE),"Missing")="Verified"),OR(M7="",IFNA(VLOOKUP(M7,$A$6:$H$6,8,FALSE),"Missing")="Verified"),OR(N7="",IFNA(VLOOKUP(N7,$A$6:$H$6,8,FALSE),"Missing")="Verified")),"Ready","Dependency open") -> Dependency open | P7: Named cook/buyer, authority and before-cooking trigger documented | Q7: Product strategy scope decision | S7: 6000 | T7: REQ-SCOPE-01 | U7: Proposed work; implementation not authorized by this documentation request. | V7: Planning
A8: P00.01.03 | B8: P00 | C8: P00.01 Product and evidence | D8: Approve one-lane demo boundary | E8: Product owner | F8: Not started | G8: FALSE | H8: =IF(COUNTIFS($A$6:$A$161,A8)<>1,"Duplicate ID",IF(O8<>"Ready","Dependency open",IF(G8=TRUE,IF(AND(F8="Complete",I8<>"",J8<>"",K8<>""),"Verified","Evidence required"),IF(F8="Complete","Check completion",IF(F8="Blocked","Blocked",IF(F8="In progress","In progress",IF(F8="In review","In review","Open"))))))) -> Dependency open | L8: P00.01.02 | O8: =IF(AND(OR(L8="",IFNA(VLOOKUP(L8,$A$6:$H$7,8,FALSE),"Missing")="Verified"),OR(M8="",IFNA(VLOOKUP(M8,$A$6:$H$7,8,FALSE),"Missing")="Verified"),OR(N8="",IFNA(VLOOKUP(N8,$A$6:$H$7,8,FALSE),"Missing")="Verified")),"Ready","Dependency open") -> Dependency open | P8: Household path chosen or alternative documented; other lanes staged | Q8: Signed scope decision DEC-PLAT-001 | S8: 6000 | T8: REQ-SCOPE-01 | U8: Proposed work; implementation not authorized by this documentation request. | V8: Planning
A9: P00.01.04 | B9: P00 | C9: P00.01 Product and evidence | D9: Define success and stop conditions | E9: Product owner | F9: Not started | G9: FALSE | H9: =IF(COUNTIFS($A$6:$A$161,A9)<>1,"Duplicate ID",IF(O9<>"Ready","Dependency open",IF(G9=TRUE,IF(AND(F9="Complete",I9<>"",J9<>"",K9<>""),"Verified","Evidence required"),IF(F9="Complete","Check completion",IF(F9="Blocked","Blocked",IF(F9="In progress","In progress",IF(F9="In review","In review","Open"))))))) -> Dependency open | L9: P00.01.03 | O9: =IF(AND(OR(L9="",IFNA(VLOOKUP(L9,$A$6:$H$8,8,FALSE),"Missing")="Verified"),OR(M9="",IFNA(VLOOKUP(M9,$A$6:$H$8,8,FALSE),"Missing")="Verified"),OR(N9="",IFNA(VLOOKUP(N9,$A$6:$H$8,8,FALSE),"Missing")="Verified")),"Ready","Dependency open") -> Dependency open | P9: Decision correctness, effort and zero unsafe actions defined before trial | Q9: Pilot/benchmark acceptance record | S9: 6000 | T9: REQ-SCOPE-01 | U9: Proposed work; implementation not authorized by this documentation request. | V9: Planning
A10: P00.02.01 | B10: P00 | C10: P00.02 Constraints and access | D10: Verify contest eligibility and deadline | E10: Technical lead | F10: Not started | G10: FALSE | H10: =IF(COUNTIFS($A$6:$A$161,A10)<>1,"Duplicate ID",IF(O10<>"Ready","Dependency open",IF(G10=TRUE,IF(AND(F10="Complete",I10<>"",J10<>"",K10<>""),"Verified","Evidence required"),IF(F10="Complete","Check completion",IF(F10="Blocked","Blocked",IF(F10="In progress","In progress",IF(F10="In review","In review","Open"))))))) -> Open | O10: =IF(AND(OR(L10="",IFNA(VLOOKUP(L10,$A$6:$H$9,8,FALSE),"Missing")="Verified"),OR(M10="",IFNA(VLOOKUP(M10,$A$6:$H$9,8,FALSE),"Missing")="Verified"),OR(N10="",IFNA(VLOOKUP(N10,$A$6:$H$9,8,FALSE),"Missing")="Verified")),"Ready","Dependency open") -> Ready | P10: Official terms, roster status and exact cutoff uncertainty recorded | Q10: Official source URLs and eligibility note | S10: 6000 | T10: REQ-SCOPE-01 | U10: Proposed work; implementation not authorized by this documentation request. | V10: Planning
A11: P00.02.02 | B11: P00 | C11: P00.02 Constraints and access | D11: Inventory cloud and model access | E11: Technical lead | F11: Not started | G11: FALSE | H11: =IF(COUNTIFS($A$6:$A$161,A11)<>1,"Duplicate ID",IF(O11<>"Ready","Dependency open",IF(G11=TRUE,IF(AND(F11="Complete",I11<>"",J11<>"",K11<>""),"Verified","Evidence required"),IF(F11="Complete","Check completion",IF(F11="Blocked","Blocked",IF(F11="In progress","In progress",IF(F11="In review","In review","Open"))))))) -> Dependency open | L11: P00.02.01 | O11: =IF(AND(OR(L11="",IFNA(VLOOKUP(L11,$A$6:$H$10,8,FALSE),"Missing")="Verified"),OR(M11="",IFNA(VLOOKUP(M11,$A$6:$H$10,8,FALSE),"Missing")="Verified"),OR(N11="",IFNA(VLOOKUP(N11,$A$6:$H$10,8,FALSE),"Missing")="Verified")),"Ready","Dependency open") -> Dependency open | P11: IAM, billing, region, quota and supported runtime verified without exposing secrets | Q11: Redacted access checklist | S11: 6000 | T11: REQ-SCOPE-01 | U11: Proposed work; implementation not authorized by this documentation request. | V11: Planning
A12: P00.02.03 | B12: P00 | C12: P00.02 Constraints and access | D12: Review food policy and measurement assumptions | E12: Technical lead | F12: Not started | G12: FALSE | H12: =IF(COUNTIFS($A$6:$A$161,A12)<>1,"Duplicate ID",IF(O12<>"Ready","Dependency open",IF(G12=TRUE,IF(AND(F12="Complete",I12<>"",J12<>"",K12<>""),"Verified","Evidence required"),IF(F12="Complete","Check completion",IF(F12="Blocked","Blocked",IF(F12="In progress","In progress",IF(F12="In review","In review","Open"))))))) -> Dependency open | L12: P00.02.02 | O12: =IF(AND(OR(L12="",IFNA(VLOOKUP(L12,$A$6:$H$11,8,FALSE),"Missing")="Verified"),OR(M12="",IFNA(VLOOKUP(M12,$A$6:$H$11,8,FALSE),"Missing")="Verified"),OR(N12="",IFNA(VLOOKUP(N12,$A$6:$H$11,8,FALSE),"Missing")="Verified")),"Ready","Dependency open") -> Dependency open | P12: Unsupported universal thresholds/cutoffs rejected; reviewer named | Q12: Policy discrepancy register | S12: 6000 | T12: REQ-SCOPE-01 | U12: Proposed work; implementation not authorized by this documentation request. | V12: Planning
A13: P00.02.04 | B13: P00 | C13: P00.02 Constraints and access | D13: Approve privacy and partner boundaries | E13: Technical lead | F13: Not started | G13: FALSE | H13: =IF(COUNTIFS($A$6:$A$161,A13)<>1,"Duplicate ID",IF(O13<>"Ready","Dependency open",IF(G13=TRUE,IF(AND(F13="Complete",I13<>"",J13<>"",K13<>""),"Verified","Evidence required"),IF(F13="Complete","Check completion",IF(F13="Blocked","Blocked",IF(F13="In progress","In progress",IF(F13="In review","In review","Open"))))))) -> Dependency open | L13: P00.02.03 | O13: =IF(AND(OR(L13="",IFNA(VLOOKUP(L13,$A$6:$H$12,8,FALSE),"Missing")="Verified"),OR(M13="",IFNA(VLOOKUP(M13,$A$6:$H$12,8,FALSE),"Missing")="Verified"),OR(N13="",IFNA(VLOOKUP(N13,$A$6:$H$12,8,FALSE),"Missing")="Verified")),"Ready","Dependency open") -> Dependency open | P13: Consent, public-repo data exclusion and simulated-only adapters specified | Q13: Privacy/partner decision record | S13: 6000 | T13: REQ-SCOPE-01 | U13: Proposed work; implementation not authorized by this documentation request. | V13: Planning
A14: P00.03.01 | B14: P00 | C14: P00.03 Execution setup | D14: Review HLD and LLD against scope | E14: Technical lead | F14: Not started | G14: FALSE | H14: =IF(COUNTIFS($A$6:$A$161,A14)<>1,"Duplicate ID",IF(O14<>"Ready","Dependency open",IF(G14=TRUE,IF(AND(F14="Complete",I14<>"",J14<>"",K14<>""),"Verified","Evidence required"),IF(F14="Complete","Check completion",IF(F14="Blocked","Blocked",IF(F14="In progress","In progress",IF(F14="In review","In review","Open"))))))) -> Open | O14: =IF(AND(OR(L14="",IFNA(VLOOKUP(L14,$A$6:$H$13,8,FALSE),"Missing")="Verified"),OR(M14="",IFNA(VLOOKUP(M14,$A$6:$H$13,8,FALSE),"Missing")="Verified"),OR(N14="",IFNA(VLOOKUP(N14,$A$6:$H$13,8,FALSE),"Missing")="Verified")),"Ready","Dependency open") -> Ready | P14: Auth, versions, approvals, idempotency and failure contracts agreed | Q14: Technical design review | S14: 6000 | T14: REQ-SCOPE-01 | U14: Proposed work; implementation not authorized by this documentation request. | V14: Planning
A15: P00.03.02 | B15: P00 | C15: P00.03 Execution setup | D15: Assign owners and estimates | E15: Technical lead | F15: Not started | G15: FALSE | H15: =IF(COUNTIFS($A$6:$A$161,A15)<>1,"Duplicate ID",IF(O15<>"Ready","Dependency open",IF(G15=TRUE,IF(AND(F15="Complete",I15<>"",J15<>"",K15<>""),"Verified","Evidence required"),IF(F15="Complete","Check completion",IF(F15="Blocked","Blocked",IF(F15="In progress","In progress",IF(F15="In review","In review","Open"))))))) -> Dependency open | L15: P00.03.01 | O15: =IF(AND(OR(L15="",IFNA(VLOOKUP(L15,$A$6:$H$14,8,FALSE),"Missing")="Verified"),OR(M15="",IFNA(VLOOKUP(M15,$A$6:$H$14,8,FALSE),"Missing")="Verified"),OR(N15="",IFNA(VLOOKUP(N15,$A$6:$H$14,8,FALSE),"Missing")="Verified")),"Ready","Dependency open") -> Dependency open | P15: Named owner, reviewer and effort for first executable work packet | Q15: Updated tracker rows | S15: 6000 | T15: REQ-SCOPE-01 | U15: Proposed work; implementation not authorized by this documentation request. | V15: Planning
A16: P00.03.03 | B16: P00 | C16: P00.03 Execution setup | D16: Exercise harness status and recovery | E16: Technical lead | F16: Not started | G16: FALSE | H16: =IF(COUNTIFS($A$6:$A$161,A16)<>1,"Duplicate ID",IF(O16<>"Ready","Dependency open",IF(G16=TRUE,IF(AND(F16="Complete",I16<>"",J16<>"",K16<>""),"Verified","Evidence required"),IF(F16="Complete","Check completion",IF(F16="Blocked","Blocked",IF(F16="In progress","In progress",IF(F16="In review","In review","Open"))))))) -> Dependency open | L16: P00.03.02 | O16: =IF(AND(OR(L16="",IFNA(VLOOKUP(L16,$A$6:$H$15,8,FALSE),"Missing")="Verified"),OR(M16="",IFNA(VLOOKUP(M16,$A$6:$H$15,8,FALSE),"Missing")="Verified"),OR(N16="",IFNA(VLOOKUP(N16,$A$6:$H$15,8,FALSE),"Missing")="Verified")),"Ready","Dependency open") -> Dependency open | P16: Checkbox alone cannot verify; dependencies and evidence gates recalculate | Q16: Harness verification record | S16: 6000 | T16: REQ-SCOPE-01 | U16: Proposed work; implementation not authorized by this documentation request. | V16: Planning
A17: P00.03.04 | B17: P00 | C17: P00.03 Execution setup | D17: Authorize implementation phase | E17: Technical lead | F17: Not started | G17: FALSE | H17: =IF(COUNTIFS($A$6:$A$161,A17)<>1,"Duplicate ID",IF(O17<>"Ready","Dependency open",IF(G17=TRUE,IF(AND(F17="Complete",I17<>"",J17<>"",K17<>""),"Verified","Evidence required"),IF(F17="Complete","Check completion",IF(F17="Blocked","Blocked",IF(F17="In progress","In progress",IF(F17="In review","In review","Open"))))))) -> Dependency open | L17: P00.03.03 | O17: =IF(AND(OR(L17="",IFNA(VLOOKUP(L17,$A$6:$H$16,8,FALSE),"Missing")="Verified"),OR(M17="",IFNA(VLOOKUP(M17,$A$6:$H$16,8,FALSE),"Missing")="Verified"),OR(N17="",IFNA(VLOOKUP(N17,$A$6:$H$16,8,FALSE),"Missing")="Verified")),"Ready","Dependency open") -> Dependency open | P17: Human authorizes coding scope; document-only restriction explicitly lifted | Q17: Authorization record | S17: 6000 | T17: REQ-SCOPE-01 | U17: Proposed work; implementation not authorized by this documentation request. | V17: Planning
A18: P00.90.01 | B18: P00 | C18: P00.90 Phase gate | D18: Review and accept planning and scope approval | E18: Product owner + independent reviewer | F18: Not started | G18: FALSE | H18: =IF(COUNTIFS($A$6:$A$161,A18)<>1,"Duplicate ID",IF(O18<>"Ready","Dependency open",IF(G18=TRUE,IF(AND(F18="Complete",I18<>"",J18<>"",K18<>""),"Verified","Evidence required"),IF(F18="Complete","Check completion",IF(F18="Blocked","Blocked",IF(F18="In progress","In progress",IF(F18="In review","In review","Open"))))))) -> Dependency open | L18: P00.01.04 | M18: P00.02.04 | N18: P00.03.04 | O18: =IF(AND(OR(L18="",IFNA(VLOOKUP(L18,$A$6:$H$17,8,FALSE),"Missing")="Verified"),OR(M18="",IFNA(VLOOKUP(M18,$A$6:$H$17,8,FALSE),"Missing")="Verified"),OR(N18="",IFNA(VLOOKUP(N18,$A$6:$H$17,8,FALSE),"Missing")="Verified")),"Ready","Dependency open") -> Dependency open | P18: All prerequisites verified; critical risks closed or explicitly rejected for rollout; human records go/revise/stop decision. | Q18: Phase gate record with reviewer, evidence links, residual risks and next scope | S18: 4000 | T18: P00-GATE | U18: Unchecked until phase evidence is reviewed. A written plan is not implementation evidence. | V18: Planning
A19: P01.01.01 | B19: P01 | C19: P01.01 Identity and permissions | D19: Define membership and permission matrix | E19: Backend engineer | F19: Not started | G19: FALSE | H19: =IF(COUNTIFS($A$6:$A$161,A19)<>1,"Duplicate ID",IF(O19<>"Ready","Dependency open",IF(G19=TRUE,IF(AND(F19="Complete",I19<>"",J19<>"",K19<>""),"Verified","Evidence required"),IF(F19="Complete","Check completion",IF(F19="Blocked","Blocked",IF(F19="In progress","In progress",IF(F19="In review","In review","Open"))))))) -> Dependency open | L19: P00.90.01 | O19: =IF(AND(OR(L19="",IFNA(VLOOKUP(L19,$A$6:$H$18,8,FALSE),"Missing")="Verified"),OR(M19="",IFNA(VLOOKUP(M19,$A$6:$H$18,8,FALSE),"Missing")="Verified"),OR(N19="",IFNA(VLOOKUP(N19,$A$6:$H$18,8,FALSE),"Missing")="Verified")),"Ready","Dependency open") -> Dependency open | P19: Each protected operation maps actor, tenant and permission | Q19: Auth contract REQ-AUTH-01 | S19: 6000 | T19: REQ-AUTH-01 / REQ-FACT-01 | U19: Proposed work; implementation not authorized by this documentation request. | V19: Demo
A20: P01.01.02 | B20: P01 | C20: P01.01 Identity and permissions | D20: Implement verified identity boundary | E20: Backend engineer | F20: Not started | G20: FALSE | H20: =IF(COUNTIFS($A$6:$A$161,A20)<>1,"Duplicate ID",IF(O20<>"Ready","Dependency open",IF(G20=TRUE,IF(AND(F20="Complete",I20<>"",J20<>"",K20<>""),"Verified","Evidence required"),IF(F20="Complete","Check completion",IF(F20="Blocked","Blocked",IF(F20="In progress","In progress",IF(F20="In review","In review","Open"))))))) -> Dependency open | L20: P01.01.01 | O20: =IF(AND(OR(L20="",IFNA(VLOOKUP(L20,$A$6:$H$19,8,FALSE),"Missing")="Verified"),OR(M20="",IFNA(VLOOKUP(M20,$A$6:$H$19,8,FALSE),"Missing")="Verified"),OR(N20="",IFNA(VLOOKUP(N20,$A$6:$H$19,8,FALSE),"Missing")="Verified")),"Ready","Dependency open") -> Dependency open | P20: Missing/invalid token rejected; tenant never defaults | Q20: Auth check evidence | S20: 6000 | T20: REQ-AUTH-01 / REQ-FACT-01 | U20: Proposed work; implementation not authorized by this documentation request. | V20: Demo
A21: P01.01.03 | B21: P01 | C21: P01.01 Identity and permissions | D21: Implement current membership and revocation checks | E21: Backend engineer | F21: Not started | G21: FALSE | H21: =IF(COUNTIFS($A$6:$A$161,A21)<>1,"Duplicate ID",IF(O21<>"Ready","Dependency open",IF(G21=TRUE,IF(AND(F21="Complete",I21<>"",J21<>"",K21<>""),"Verified","Evidence required"),IF(F21="Complete","Check completion",IF(F21="Blocked","Blocked",IF(F21="In progress","In progress",IF(F21="In review","In review","Open"))))))) -> Dependency open | L21: P01.01.02 | O21: =IF(AND(OR(L21="",IFNA(VLOOKUP(L21,$A$6:$H$20,8,FALSE),"Missing")="Verified"),OR(M21="",IFNA(VLOOKUP(M21,$A$6:$H$20,8,FALSE),"Missing")="Verified"),OR(N21="",IFNA(VLOOKUP(N21,$A$6:$H$20,8,FALSE),"Missing")="Verified")),"Ready","Dependency open") -> Dependency open | P21: Revoked membership fails even with a still-valid token | Q21: Revocation and wrong-tenant evidence | S21: 6000 | T21: REQ-AUTH-01 / REQ-FACT-01 | U21: Proposed work; implementation not authorized by this documentation request. | V21: Demo
A22: P01.01.04 | B22: P01 | C22: P01.01 Identity and permissions | D22: Prove denial across roles and tenants | E22: Backend engineer | F22: Not started | G22: FALSE | H22: =IF(COUNTIFS($A$6:$A$161,A22)<>1,"Duplicate ID",IF(O22<>"Ready","Dependency open",IF(G22=TRUE,IF(AND(F22="Complete",I22<>"",J22<>"",K22<>""),"Verified","Evidence required"),IF(F22="Complete","Check completion",IF(F22="Blocked","Blocked",IF(F22="In progress","In progress",IF(F22="In review","In review","Open"))))))) -> Dependency open | L22: P01.01.03 | O22: =IF(AND(OR(L22="",IFNA(VLOOKUP(L22,$A$6:$H$21,8,FALSE),"Missing")="Verified"),OR(M22="",IFNA(VLOOKUP(M22,$A$6:$H$21,8,FALSE),"Missing")="Verified"),OR(N22="",IFNA(VLOOKUP(N22,$A$6:$H$21,8,FALSE),"Missing")="Verified")),"Ready","Dependency open") -> Dependency open | P22: Read/write isolation and guessed IDs tested | Q22: Negative authorization matrix | S22: 6000 | T22: REQ-AUTH-01 / REQ-FACT-01 | U22: Proposed work; implementation not authorized by this documentation request. | V22: Demo
A23: P01.02.01 | B23: P01 | C23: P01.02 Canonical records | D23: Define typed records and units | E23: Backend engineer | F23: Not started | G23: FALSE | H23: =IF(COUNTIFS($A$6:$A$161,A23)<>1,"Duplicate ID",IF(O23<>"Ready","Dependency open",IF(G23=TRUE,IF(AND(F23="Complete",I23<>"",J23<>"",K23<>""),"Verified","Evidence required"),IF(F23="Complete","Check completion",IF(F23="Blocked","Blocked",IF(F23="In progress","In progress",IF(F23="In review","In review","Open"))))))) -> Dependency open | L23: P00.90.01 | O23: =IF(AND(OR(L23="",IFNA(VLOOKUP(L23,$A$6:$H$22,8,FALSE),"Missing")="Verified"),OR(M23="",IFNA(VLOOKUP(M23,$A$6:$H$22,8,FALSE),"Missing")="Verified"),OR(N23="",IFNA(VLOOKUP(N23,$A$6:$H$22,8,FALSE),"Missing")="Verified")),"Ready","Dependency open") -> Dependency open | P23: Candidate, fact, proposal, evidence, outcome schemas include version and provenance | Q23: Schema review | S23: 6000 | T23: REQ-AUTH-01 / REQ-FACT-01 | U23: Proposed work; implementation not authorized by this documentation request. | V23: Demo
A24: P01.02.02 | B24: P01 | C24: P01.02 Canonical records | D24: Define tenant paths and server-only writes | E24: Backend engineer | F24: Not started | G24: FALSE | H24: =IF(COUNTIFS($A$6:$A$161,A24)<>1,"Duplicate ID",IF(O24<>"Ready","Dependency open",IF(G24=TRUE,IF(AND(F24="Complete",I24<>"",J24<>"",K24<>""),"Verified","Evidence required"),IF(F24="Complete","Check completion",IF(F24="Blocked","Blocked",IF(F24="In progress","In progress",IF(F24="In review","In review","Open"))))))) -> Dependency open | L24: P01.02.01 | O24: =IF(AND(OR(L24="",IFNA(VLOOKUP(L24,$A$6:$H$23,8,FALSE),"Missing")="Verified"),OR(M24="",IFNA(VLOOKUP(M24,$A$6:$H$23,8,FALSE),"Missing")="Verified"),OR(N24="",IFNA(VLOOKUP(N24,$A$6:$H$23,8,FALSE),"Missing")="Verified")),"Ready","Dependency open") -> Dependency open | P24: No global list or browser mutation bypass; server IAM assessed | Q24: Firestore access design | S24: 6000 | T24: REQ-AUTH-01 / REQ-FACT-01 | U24: Proposed work; implementation not authorized by this documentation request. | V24: Demo
A25: P01.02.03 | B25: P01 | C25: P01.02 Canonical records | D25: Implement atomic versioned confirmation | E25: Backend engineer | F25: Not started | G25: FALSE | H25: =IF(COUNTIFS($A$6:$A$161,A25)<>1,"Duplicate ID",IF(O25<>"Ready","Dependency open",IF(G25=TRUE,IF(AND(F25="Complete",I25<>"",J25<>"",K25<>""),"Verified","Evidence required"),IF(F25="Complete","Check completion",IF(F25="Blocked","Blocked",IF(F25="In progress","In progress",IF(F25="In review","In review","Open"))))))) -> Dependency open | L25: P01.02.02 | O25: =IF(AND(OR(L25="",IFNA(VLOOKUP(L25,$A$6:$H$24,8,FALSE),"Missing")="Verified"),OR(M25="",IFNA(VLOOKUP(M25,$A$6:$H$24,8,FALSE),"Missing")="Verified"),OR(N25="",IFNA(VLOOKUP(N25,$A$6:$H$24,8,FALSE),"Missing")="Verified")),"Ready","Dependency open") -> Dependency open | P25: Stale version causes conflict; repeat submission does not duplicate facts | Q25: Confirmation conflict evidence | S25: 6000 | T25: REQ-AUTH-01 / REQ-FACT-01 | U25: Proposed work; implementation not authorized by this documentation request. | V25: Demo
A26: P01.02.04 | B26: P01 | C26: P01.02 Canonical records | D26: Prove durable audit and restart behavior | E26: Backend engineer | F26: Not started | G26: FALSE | H26: =IF(COUNTIFS($A$6:$A$161,A26)<>1,"Duplicate ID",IF(O26<>"Ready","Dependency open",IF(G26=TRUE,IF(AND(F26="Complete",I26<>"",J26<>"",K26<>""),"Verified","Evidence required"),IF(F26="Complete","Check completion",IF(F26="Blocked","Blocked",IF(F26="In progress","In progress",IF(F26="In review","In review","Open"))))))) -> Dependency open | L26: P01.02.03 | O26: =IF(AND(OR(L26="",IFNA(VLOOKUP(L26,$A$6:$H$25,8,FALSE),"Missing")="Verified"),OR(M26="",IFNA(VLOOKUP(M26,$A$6:$H$25,8,FALSE),"Missing")="Verified"),OR(N26="",IFNA(VLOOKUP(N26,$A$6:$H$25,8,FALSE),"Missing")="Verified")),"Ready","Dependency open") -> Dependency open | P26: Business state survives restart; sensitive content excluded from logs | Q26: Persistence and redaction evidence | S26: 6000 | T26: REQ-AUTH-01 / REQ-FACT-01 | U26: Proposed work; implementation not authorized by this documentation request. | V26: Demo
A27: P01.03.01 | B27: P01 | C27: P01.03 Runtime foundation | D27: Confirm supported frontend and Node pairing | E27: Platform engineer | F27: Not started | G27: FALSE | H27: =IF(COUNTIFS($A$6:$A$161,A27)<>1,"Duplicate ID",IF(O27<>"Ready","Dependency open",IF(G27=TRUE,IF(AND(F27="Complete",I27<>"",J27<>"",K27<>""),"Verified","Evidence required"),IF(F27="Complete","Check completion",IF(F27="Blocked","Blocked",IF(F27="In progress","In progress",IF(F27="In review","In review","Open"))))))) -> Dependency open | L27: P00.90.01 | O27: =IF(AND(OR(L27="",IFNA(VLOOKUP(L27,$A$6:$H$26,8,FALSE),"Missing")="Verified"),OR(M27="",IFNA(VLOOKUP(M27,$A$6:$H$26,8,FALSE),"Missing")="Verified"),OR(N27="",IFNA(VLOOKUP(N27,$A$6:$H$26,8,FALSE),"Missing")="Verified")),"Ready","Dependency open") -> Dependency open | P27: App Hosting compatibility verified for actual pinned versions | Q27: Runtime matrix | S27: 6000 | T27: REQ-AUTH-01 / REQ-FACT-01 | U27: Proposed work; implementation not authorized by this documentation request. | V27: Demo
A28: P01.03.02 | B28: P01 | C28: P01.03 Runtime foundation | D28: Configure authenticated API client and origins | E28: Platform engineer | F28: Not started | G28: FALSE | H28: =IF(COUNTIFS($A$6:$A$161,A28)<>1,"Duplicate ID",IF(O28<>"Ready","Dependency open",IF(G28=TRUE,IF(AND(F28="Complete",I28<>"",J28<>"",K28<>""),"Verified","Evidence required"),IF(F28="Complete","Check completion",IF(F28="Blocked","Blocked",IF(F28="In progress","In progress",IF(F28="In review","In review","Open"))))))) -> Dependency open | L28: P01.03.01 | O28: =IF(AND(OR(L28="",IFNA(VLOOKUP(L28,$A$6:$H$27,8,FALSE),"Missing")="Verified"),OR(M28="",IFNA(VLOOKUP(M28,$A$6:$H$27,8,FALSE),"Missing")="Verified"),OR(N28="",IFNA(VLOOKUP(N28,$A$6:$H$27,8,FALSE),"Missing")="Verified")),"Ready","Dependency open") -> Dependency open | P28: Environment URL used; production origins explicit; localhost not shipped | Q28: Client/CORS evidence | S28: 6000 | T28: REQ-AUTH-01 / REQ-FACT-01 | U28: Proposed work; implementation not authorized by this documentation request. | V28: Demo
A29: P01.03.03 | B29: P01 | C29: P01.03 Runtime foundation | D29: Create health and deployment contract | E29: Platform engineer | F29: Not started | G29: FALSE | H29: =IF(COUNTIFS($A$6:$A$161,A29)<>1,"Duplicate ID",IF(O29<>"Ready","Dependency open",IF(G29=TRUE,IF(AND(F29="Complete",I29<>"",J29<>"",K29<>""),"Verified","Evidence required"),IF(F29="Complete","Check completion",IF(F29="Blocked","Blocked",IF(F29="In progress","In progress",IF(F29="In review","In review","Open"))))))) -> Dependency open | L29: P01.03.02 | O29: =IF(AND(OR(L29="",IFNA(VLOOKUP(L29,$A$6:$H$28,8,FALSE),"Missing")="Verified"),OR(M29="",IFNA(VLOOKUP(M29,$A$6:$H$28,8,FALSE),"Missing")="Verified"),OR(N29="",IFNA(VLOOKUP(N29,$A$6:$H$28,8,FALSE),"Missing")="Verified")),"Ready","Dependency open") -> Dependency open | P29: Root health path stable; PORT and startup behavior documented | Q29: Health/deployment smoke evidence | S29: 6000 | T29: REQ-AUTH-01 / REQ-FACT-01 | U29: Proposed work; implementation not authorized by this documentation request. | V29: Demo
A30: P01.03.04 | B30: P01 | C30: P01.03 Runtime foundation | D30: Set budgets and model call caps | E30: Platform engineer | F30: Not started | G30: FALSE | H30: =IF(COUNTIFS($A$6:$A$161,A30)<>1,"Duplicate ID",IF(O30<>"Ready","Dependency open",IF(G30=TRUE,IF(AND(F30="Complete",I30<>"",J30<>"",K30<>""),"Verified","Evidence required"),IF(F30="Complete","Check completion",IF(F30="Blocked","Blocked",IF(F30="In progress","In progress",IF(F30="In review","In review","Open"))))))) -> Dependency open | L30: P01.03.03 | O30: =IF(AND(OR(L30="",IFNA(VLOOKUP(L30,$A$6:$H$29,8,FALSE),"Missing")="Verified"),OR(M30="",IFNA(VLOOKUP(M30,$A$6:$H$29,8,FALSE),"Missing")="Verified"),OR(N30="",IFNA(VLOOKUP(N30,$A$6:$H$29,8,FALSE),"Missing")="Verified")),"Ready","Dependency open") -> Dependency open | P30: Quota, maximum attempts/tokens and alerts have owners | Q30: Budget configuration evidence | S30: 6000 | T30: REQ-AUTH-01 / REQ-FACT-01 | U30: Proposed work; implementation not authorized by this documentation request. | V30: Demo
A31: P01.90.01 | B31: P01 | C31: P01.90 Phase gate | D31: Review and accept trusted foundation and contracts | E31: Product owner + independent reviewer | F31: Not started | G31: FALSE | H31: =IF(COUNTIFS($A$6:$A$161,A31)<>1,"Duplicate ID",IF(O31<>"Ready","Dependency open",IF(G31=TRUE,IF(AND(F31="Complete",I31<>"",J31<>"",K31<>""),"Verified","Evidence required"),IF(F31="Complete","Check completion",IF(F31="Blocked","Blocked",IF(F31="In progress","In progress",IF(F31="In review","In review","Open"))))))) -> Dependency open | L31: P01.01.04 | M31: P01.02.04 | N31: P01.03.04 | O31: =IF(AND(OR(L31="",IFNA(VLOOKUP(L31,$A$6:$H$30,8,FALSE),"Missing")="Verified"),OR(M31="",IFNA(VLOOKUP(M31,$A$6:$H$30,8,FALSE),"Missing")="Verified"),OR(N31="",IFNA(VLOOKUP(N31,$A$6:$H$30,8,FALSE),"Missing")="Verified")),"Ready","Dependency open") -> Dependency open | P31: All prerequisites verified; critical risks closed or explicitly rejected for rollout; human records go/revise/stop decision. | Q31: Phase gate record with reviewer, evidence links, residual risks and next scope | S31: 4000 | T31: P01-GATE | U31: Unchecked until phase evidence is reviewed. A written plan is not implementation evidence. | V31: Demo
A32: P02.01.01 | B32: P02 | C32: P02.01 Decision rules | D32: Specify pantry and meal change fixtures | E32: Backend engineer | F32: Not started | G32: FALSE | H32: =IF(COUNTIFS($A$6:$A$161,A32)<>1,"Duplicate ID",IF(O32<>"Ready","Dependency open",IF(G32=TRUE,IF(AND(F32="Complete",I32<>"",J32<>"",K32<>""),"Verified","Evidence required"),IF(F32="Complete","Check completion",IF(F32="Blocked","Blocked",IF(F32="In progress","In progress",IF(F32="In review","In review","Open"))))))) -> Dependency open | L32: P01.90.01 | O32: =IF(AND(OR(L32="",IFNA(VLOOKUP(L32,$A$6:$H$31,8,FALSE),"Missing")="Verified"),OR(M32="",IFNA(VLOOKUP(M32,$A$6:$H$31,8,FALSE),"Missing")="Verified"),OR(N32="",IFNA(VLOOKUP(N32,$A$6:$H$31,8,FALSE),"Missing")="Verified")),"Ready","Dependency open") -> Dependency open | P32: Stock freshness, ownership, units and consumed quantities explicit | Q32: Fixture definitions | S32: 6000 | T32: J-H01 / REQ-ACT-01 | U32: Proposed work; implementation not authorized by this documentation request. | V32: Demo
A33: P02.01.02 | B33: P02 | C33: P02.01 Decision rules | D33: Implement unit-safe quantity reconciliation | E33: Backend engineer | F33: Not started | G33: FALSE | H33: =IF(COUNTIFS($A$6:$A$161,A33)<>1,"Duplicate ID",IF(O33<>"Ready","Dependency open",IF(G33=TRUE,IF(AND(F33="Complete",I33<>"",J33<>"",K33<>""),"Verified","Evidence required"),IF(F33="Complete","Check completion",IF(F33="Blocked","Blocked",IF(F33="In progress","In progress",IF(F33="In review","In review","Open"))))))) -> Dependency open | L33: P02.01.01 | O33: =IF(AND(OR(L33="",IFNA(VLOOKUP(L33,$A$6:$H$32,8,FALSE),"Missing")="Verified"),OR(M33="",IFNA(VLOOKUP(M33,$A$6:$H$32,8,FALSE),"Missing")="Verified"),OR(N33="",IFNA(VLOOKUP(N33,$A$6:$H$32,8,FALSE),"Missing")="Verified")),"Ready","Dependency open") -> Dependency open | P33: No g/ml conversion without verified factor; no negative stock | Q33: Boundary-case outputs | S33: 6000 | T33: J-H01 / REQ-ACT-01 | U33: Proposed work; implementation not authorized by this documentation request. | V33: Demo
A34: P02.01.03 | B34: P02 | C34: P02.01 Decision rules | D34: Implement portion and cutoff rules | E34: Backend engineer | F34: Not started | G34: FALSE | H34: =IF(COUNTIFS($A$6:$A$161,A34)<>1,"Duplicate ID",IF(O34<>"Ready","Dependency open",IF(G34=TRUE,IF(AND(F34="Complete",I34<>"",J34<>"",K34<>""),"Verified","Evidence required"),IF(F34="Complete","Check completion",IF(F34="Blocked","Blocked",IF(F34="In progress","In progress",IF(F34="In review","In review","Open"))))))) -> Dependency open | L34: P02.01.02 | O34: =IF(AND(OR(L34="",IFNA(VLOOKUP(L34,$A$6:$H$33,8,FALSE),"Missing")="Verified"),OR(M34="",IFNA(VLOOKUP(M34,$A$6:$H$33,8,FALSE),"Missing")="Verified"),OR(N34="",IFNA(VLOOKUP(N34,$A$6:$H$33,8,FALSE),"Missing")="Verified")),"Ready","Dependency open") -> Dependency open | P34: Zero diners and after-cutoff behavior deterministic and explained | Q34: Rule-case outputs | S34: 6000 | T34: J-H01 / REQ-ACT-01 | U34: Proposed work; implementation not authorized by this documentation request. | V34: Demo
A35: P02.01.04 | B35: P02 | C35: P02.01 Decision rules | D35: Implement immutable simulated proposal | E35: Backend engineer | F35: Not started | G35: FALSE | H35: =IF(COUNTIFS($A$6:$A$161,A35)<>1,"Duplicate ID",IF(O35<>"Ready","Dependency open",IF(G35=TRUE,IF(AND(F35="Complete",I35<>"",J35<>"",K35<>""),"Verified","Evidence required"),IF(F35="Complete","Check completion",IF(F35="Blocked","Blocked",IF(F35="In progress","In progress",IF(F35="In review","In review","Open"))))))) -> Dependency open | L35: P02.01.03 | O35: =IF(AND(OR(L35="",IFNA(VLOOKUP(L35,$A$6:$H$34,8,FALSE),"Missing")="Verified"),OR(M35="",IFNA(VLOOKUP(M35,$A$6:$H$34,8,FALSE),"Missing")="Verified"),OR(N35="",IFNA(VLOOKUP(N35,$A$6:$H$34,8,FALSE),"Missing")="Verified")),"Ready","Dependency open") -> Dependency open | P35: Snapshot versions, expiry and preview hash stored; simulated true | Q35: Proposal contract evidence | S35: 6000 | T35: J-H01 / REQ-ACT-01 | U35: Proposed work; implementation not authorized by this documentation request. | V35: Demo
A36: P02.02.01 | B36: P02 | C36: P02.02 Evaluation baseline | D36: Annotate household gold cases | E36: Evaluation reviewer | F36: Not started | G36: FALSE | H36: =IF(COUNTIFS($A$6:$A$161,A36)<>1,"Duplicate ID",IF(O36<>"Ready","Dependency open",IF(G36=TRUE,IF(AND(F36="Complete",I36<>"",J36<>"",K36<>""),"Verified","Evidence required"),IF(F36="Complete","Check completion",IF(F36="Blocked","Blocked",IF(F36="In progress","In progress",IF(F36="In review","In review","Open"))))))) -> Dependency open | L36: P01.90.01 | O36: =IF(AND(OR(L36="",IFNA(VLOOKUP(L36,$A$6:$H$35,8,FALSE),"Missing")="Verified"),OR(M36="",IFNA(VLOOKUP(M36,$A$6:$H$35,8,FALSE),"Missing")="Verified"),OR(N36="",IFNA(VLOOKUP(N36,$A$6:$H$35,8,FALSE),"Missing")="Verified")),"Ready","Dependency open") -> Dependency open | P36: Labels and rejection reasons independently reviewed | Q36: Gold-case register | S36: 6000 | T36: J-H01 / REQ-ACT-01 | U36: Proposed work; implementation not authorized by this documentation request. | V36: Demo
A37: P02.02.02 | B37: P02 | C37: P02.02 Evaluation baseline | D37: Run rules-only baseline | E37: Evaluation reviewer | F37: Not started | G37: FALSE | H37: =IF(COUNTIFS($A$6:$A$161,A37)<>1,"Duplicate ID",IF(O37<>"Ready","Dependency open",IF(G37=TRUE,IF(AND(F37="Complete",I37<>"",J37<>"",K37<>""),"Verified","Evidence required"),IF(F37="Complete","Check completion",IF(F37="Blocked","Blocked",IF(F37="In progress","In progress",IF(F37="In review","In review","Open"))))))) -> Dependency open | L37: P02.02.01 | O37: =IF(AND(OR(L37="",IFNA(VLOOKUP(L37,$A$6:$H$36,8,FALSE),"Missing")="Verified"),OR(M37="",IFNA(VLOOKUP(M37,$A$6:$H$36,8,FALSE),"Missing")="Verified"),OR(N37="",IFNA(VLOOKUP(N37,$A$6:$H$36,8,FALSE),"Missing")="Verified")),"Ready","Dependency open") -> Dependency open | P37: Fixed input fixtures and privileges; raw results retained | Q37: Baseline run ID | S37: 6000 | T37: J-H01 / REQ-ACT-01 | U37: Proposed work; implementation not authorized by this documentation request. | V37: Demo
A38: P02.02.03 | B38: P02 | C38: P02.02 Evaluation baseline | D38: Add adversarial and concurrency assertions | E38: Evaluation reviewer | F38: Not started | G38: FALSE | H38: =IF(COUNTIFS($A$6:$A$161,A38)<>1,"Duplicate ID",IF(O38<>"Ready","Dependency open",IF(G38=TRUE,IF(AND(F38="Complete",I38<>"",J38<>"",K38<>""),"Verified","Evidence required"),IF(F38="Complete","Check completion",IF(F38="Blocked","Blocked",IF(F38="In progress","In progress",IF(F38="In review","In review","Open"))))))) -> Dependency open | L38: P02.02.02 | O38: =IF(AND(OR(L38="",IFNA(VLOOKUP(L38,$A$6:$H$37,8,FALSE),"Missing")="Verified"),OR(M38="",IFNA(VLOOKUP(M38,$A$6:$H$37,8,FALSE),"Missing")="Verified"),OR(N38="",IFNA(VLOOKUP(N38,$A$6:$H$37,8,FALSE),"Missing")="Verified")),"Ready","Dependency open") -> Dependency open | P38: Injected text, stale facts and approval races covered | Q38: Negative-case results | S38: 6000 | T38: J-H01 / REQ-ACT-01 | U38: Proposed work; implementation not authorized by this documentation request. | V38: Demo
A39: P02.02.04 | B39: P02 | C39: P02.02 Evaluation baseline | D39: Define fair comparison protocol | E39: Evaluation reviewer | F39: Not started | G39: FALSE | H39: =IF(COUNTIFS($A$6:$A$161,A39)<>1,"Duplicate ID",IF(O39<>"Ready","Dependency open",IF(G39=TRUE,IF(AND(F39="Complete",I39<>"",J39<>"",K39<>""),"Verified","Evidence required"),IF(F39="Complete","Check completion",IF(F39="Blocked","Blocked",IF(F39="In progress","In progress",IF(F39="In review","In review","Open"))))))) -> Dependency open | L39: P02.02.03 | O39: =IF(AND(OR(L39="",IFNA(VLOOKUP(L39,$A$6:$H$38,8,FALSE),"Missing")="Verified"),OR(M39="",IFNA(VLOOKUP(M39,$A$6:$H$38,8,FALSE),"Missing")="Verified"),OR(N39="",IFNA(VLOOKUP(N39,$A$6:$H$38,8,FALSE),"Missing")="Verified")),"Ready","Dependency open") -> Dependency open | P39: Equivalent inputs, model budget and reporting denominator frozen | Q39: Evaluation protocol | S39: 6000 | T39: J-H01 / REQ-ACT-01 | U39: Proposed work; implementation not authorized by this documentation request. | V39: Demo
A40: P02.03.01 | B40: P02 | C40: P02.03 Human workflow | D40: Build synthetic scenario start and actor view | E40: Frontend engineer | F40: Not started | G40: FALSE | H40: =IF(COUNTIFS($A$6:$A$161,A40)<>1,"Duplicate ID",IF(O40<>"Ready","Dependency open",IF(G40=TRUE,IF(AND(F40="Complete",I40<>"",J40<>"",K40<>""),"Verified","Evidence required"),IF(F40="Complete","Check completion",IF(F40="Blocked","Blocked",IF(F40="In progress","In progress",IF(F40="In review","In review","Open"))))))) -> Dependency open | L40: P01.90.01 | O40: =IF(AND(OR(L40="",IFNA(VLOOKUP(L40,$A$6:$H$39,8,FALSE),"Missing")="Verified"),OR(M40="",IFNA(VLOOKUP(M40,$A$6:$H$39,8,FALSE),"Missing")="Verified"),OR(N40="",IFNA(VLOOKUP(N40,$A$6:$H$39,8,FALSE),"Missing")="Verified")),"Ready","Dependency open") -> Dependency open | P40: Demo tenant and simulated records conspicuous | Q40: Scenario screen evidence | S40: 6000 | T40: J-H01 / REQ-ACT-01 | U40: Proposed work; implementation not authorized by this documentation request. | V40: Demo
A41: P02.03.02 | B41: P02 | C41: P02.03 Human workflow | D41: Build candidate/fact review interaction | E41: Frontend engineer | F41: Not started | G41: FALSE | H41: =IF(COUNTIFS($A$6:$A$161,A41)<>1,"Duplicate ID",IF(O41<>"Ready","Dependency open",IF(G41=TRUE,IF(AND(F41="Complete",I41<>"",J41<>"",K41<>""),"Verified","Evidence required"),IF(F41="Complete","Check completion",IF(F41="Blocked","Blocked",IF(F41="In progress","In progress",IF(F41="In review","In review","Open"))))))) -> Dependency open | L41: P02.03.01 | O41: =IF(AND(OR(L41="",IFNA(VLOOKUP(L41,$A$6:$H$40,8,FALSE),"Missing")="Verified"),OR(M41="",IFNA(VLOOKUP(M41,$A$6:$H$40,8,FALSE),"Missing")="Verified"),OR(N41="",IFNA(VLOOKUP(N41,$A$6:$H$40,8,FALSE),"Missing")="Verified")),"Ready","Dependency open") -> Dependency open | P41: Field changes explicit; confirm distinct from extraction | Q41: Review-flow evidence | S41: 6000 | T41: J-H01 / REQ-ACT-01 | U41: Proposed work; implementation not authorized by this documentation request. | V41: Demo
...

Sheet Decisions
A1: Decisions and tradeoffs
A2: Proposed / recommended is not human approval. Record evidence, approver and date when resolved.
A5: Decision ID | B5: Choice | C5: Disposition | D5: Recommendation | E5: Alternatives | F5: Reason | G5: Owner role | H5: Linked unit | I5: Revisit trigger | J5: Evidence | K5: Approver | L5: Decision date
A6: DEC-PLAT-001 | B6: First implementation lane | C6: Proposed | D6: One household changed-plan journey; switch to kitchen first only with better actor/data access | E6: Three full lanes at once; generic material marketplace | F6: Small enough to prove the shared loop; competition and residual gap still unknown | G6: Product owner | H6: P00.01.03 | I6: Observed actor access and residual pain change the preferred lane
A7: DEC-PLAT-002 | B7: Platform expansion | C7: Proposed | D7: Shared trust/evidence/action core with separately gated domain modules | E7: One universal resource engine; separate disconnected apps | F7: Reuse coordination contracts without conflating food safety, repair and meter authority | G7: Product owner + technical lead | H7: P08.90.01 | I7: Second domain cannot reuse core safely or does not show demand
A8: DEC-PLAT-003 | B8: Backend structure | C8: Recommended | D8: Modular FastAPI monolith and bounded worker when required | E8: Microservices from day one; frontend-only logic | F8: Fewer transaction and deployment seams while preserving domain boundaries | G8: Technical lead | H8: P01.90.01 | I8: Measured scaling, security ownership or release independence justifies split
A9: DEC-PLAT-004 | B9: Runtime compatibility | C9: Open | D9: Verify current Next.js/Node support on App Hosting before pinning deployment pair | E9: Assume repo version works; automatically downgrade | F9: Existing package version and retrieved support schedule differ; no deploy proof | G9: Platform lead | H9: P01.03.01 | I9: Official support or a measured deployed compatibility test settles pair
A10: DEC-PLAT-005 | B10: Canonical storage | C10: Existing stack constraint | D10: Firestore versioned document state and Cloud Storage media; reevaluate relational needs later | E10: PostgreSQL now; in-memory canonical state | F10: Fits selected stack and bounded workflows; cross-org joins need careful projections | G10: Technical lead | H10: P01.02.04 | I10: Transaction contention or reporting constraints dominate
A11: DEC-PLAT-006 | B11: Authorization | C11: Required invariant | D11: Verified identity plus active membership, role, consent and resource scope; fail closed | E11: Trust body tenant ID; default tenant; token-only organization membership | F11: Prevent cross-tenant reads and stale authority after revocation | G11: Security/backend lead | H11: P01.01.04 | I11: No relaxation; improve implementation with equivalent or stronger proof
A12: DEC-PLAT-007 | B12: Facts and approvals | C12: Required invariant | D12: Candidate isolation; explicit confirmation; immutable version-bound preview and authorized approval | E12: Agent writes facts or self-authorizes execution | F12: Human authority and current source state govern every physical effect | G12: Technical lead | H12: P03.02.04 | I12: No relaxation; contract changes require migration and denial checks
A13: DEC-PLAT-008 | B13: Food policy | C13: Required invariant | D13: Reviewed category/site policy bundles; missing applicability holds for review | E13: Universal hardcoded time/temperature thresholds from examples | F13: Current local shortcuts are not established by cited rule text | G13: Qualified policy owner | H13: P06.01.01 | I13: Reviewed official amendment or site policy updates versioned bundle
A14: DEC-PLAT-009 | B14: AI structure | C14: Recommended | D14: Structured extraction and one bounded allowlisted ADK coordinator, evaluated separately | E14: Multi-agent product runtime; unlimited tool loop; rules-only forever | F14: AI may help ambiguity; arithmetic and authority stay deterministic | G14: AI lead | H14: P03.03.04 | I14: Comparison shows a step adds no benefit or a justified workflow needs more
A15: DEC-PLAT-010 | B15: Policy retrieval | C15: Deferred | D15: Small reviewed rule table and source links first | E15: Vertex AI Search/RAG immediately | F15: Corpus size and retrieval need are unproven; retrieved prose cannot publish policy | G15: Policy/AI lead | H15: P06.01.01 | I15: Authorized corpus and real questions show retrieval improves the task
A16: DEC-PLAT-011 | B16: Jobs and external actions | C16: Recommended | D16: Outbox plus idempotent worker for durable effects; reconcile ambiguous provider states | E16: Provider call inside transaction; blind retry after timeout | F16: Transactions can retry and networks duplicate or hide successful effects | G16: Backend lead | H16: P03.02.04 | I16: A synchronous bounded demo needs no durable external work; keep effect boundary
A17: DEC-PLAT-012 | B17: Product real-time behavior | C17: Recommended | D17: Bounded polling with versions initially; scoped events only after measured need | E17: Persistent streams everywhere; unscoped global listeners | F17: Recoverable and easier to secure; acknowledgement and timestamps matter first | G17: Fullstack lead | H17: P03.03.03 | I17: Collaboration latency/read costs justify streams
... A25: DEC-PLAT-020 | B25: Current work authorization | C25: User constraint | D25: Documentation/research and live planning artifacts only; implementation requires later direction | E25: Treat this request as permission to modify application code or deploy | F25: User explicitly requested ideation, tradeoffs and feasibility with no code changes | G25: Product owner | H25: P00.03.04 | I25: User explicitly authorizes implementation scope

Sheet Risks
A1: Risks and next evidence
A5: Risk ID | B5: Risk | C5: State | D5: Trigger | E5: Response / next evidence | F5: Owner role | G5: Linked unit | H5: Evidence / update | I5: Disposition
A6: RISK-01 | B6: Residual pain unproven | C6: Open | D6: Existing list/service handles chosen cases | E6: Reconstruct real episodes and compare baseline | F6: Product owner | G6: P00.01.02 | I6: Unresolved
A7: RISK-02 | B7: Data rights or authority unavailable | C7: Open | D7: No consenting source/decision owner | E7: Obtain artifact rights or defer feature | F7: Research lead | G7: P00.02.04 | I7: Unresolved
A8: RISK-03 | B8: Unsafe policy shortcut | C8: Open | D8: Unreviewed threshold or food-safety claim | E8: Block live recovery; qualified policy review | F8: Policy owner | G8: P06.01.01 | I8: Unresolved
A9: RISK-04 | B9: Deployment or model access blocked | C9: Open | D9: Unsupported runtime/IAM/quota | E9: Verify early and cut optional scope | F9: Platform lead | G9: P01.03.01 | I9: Unresolved
A10: RISK-05 | B10: Input burden exceeds benefit | C10: Open | D10: Corrections take longer than baseline | E10: Measure all actor effort; redesign capture | F10: Product lead | G10: P08.01.03 | I10: Unresolved
A11: RISK-06 | B11: AI adds no incremental value | C11: Open | D11: No better correctness/effort net of cost | E11: Keep rules; remove unnecessary model step | F11: AI/evaluation lead | G11: P03.03.04 | I11: Unresolved
A12: RISK-07 | B12: Physical logistics dominates | C12: Open | D12: No safe capacity or processing destination | E12: Audit failures; a directory cannot create capacity | F12: Partner lead | G12: P06.02.02 | I12: Unresolved
A13: RISK-08 | B13: Impact overclaim/double counting | C13: Open | D13: Simulation shown as measured saving | E13: Separate stage, origin, verification and attribution | F13: Measurement lead | G13: P08.03.04 | I13: Unresolved
A14: RISK-09 | B14: Economics or payer unproven | C14: Open | D14: Support exceeds payer value | E14: Measure costs and real pricing response | F14: Product owner | G14: P08.02.04 | I14: Unresolved
A15: RISK-10 | B15: Context drift/false completion | C15: Open | D15: Missing evidence or duplicate live status | E15: Stable IDs, gates and session handoff | F15: Technical lead | G15: P00.03.03 | I15: Unresolved

Sheet Sessions
A1: Session handoffs
A5: Session ID | B5: Date (IST) | C5: Scope | D5: Units / artifacts | E5: Evidence | F5: Result | G5: Open blocker | H5: Next unit | I5: Decisions | J5: Usage note
A6: S-2026-10-15-01 | B6: 2026-10-15 | C6: Research and documentation only | D6: 42 sources; blueprint + 156-unit plan | E6: Control room/source register | F6: Documentation prepared; implementation unverified | G6: Human review, access and scope decisions pending | H6: P00.01.01 | I6: DEC-PLAT-001–020 as labeled | J6: Actual account budget unknown; bounded task packets

Sheet Guide
A1: How to keep this harness current
A5: Topic | B5: Operating rule
A6: Authority | B6: Tasks is live status; Docs are narrative; local files are snapshots.
A7: Completion | B7: Set Complete + Done + evidence + reviewer + updated date. Dependencies must be Verified.
A8: Formula limit | B8: Use filters, not physical sorting. Dependencies must point to earlier unique IDs; missing/later IDs fail closed.
A9: Adding work | B9: Append unique IDs after prerequisites, copy formulas/validation, extend bounded ranges and update phase gates.
A10: No background sync | B10: No repository monitor, CI integration, agent scheduler or two-way Drive sync is implemented.
A11: Ownership | B11: Initial owners are roles. Assign actual people/agents before execution.
A12: Token allowance | B12: 6,000 context tokens/unit is a planning input; actual output/tool/delegation usage varies.
A13: Evidence quality | B13: Formulas check presence/state, not truth, safety qualification or link accessibility.
A14: Scope | B14: Documentation only. Later code, deployment and physical effects require relevant direction.
A15: Review | B15: Critical auth/safety/data-loss review first, then maintainability, UX and missing checks.
A16: Recovery | B16: Back up before structural changes; preserve IDs, revisions, failed output and decisions.
A17: Source folder | B17: https://drive.google.com/drive/folders/1iTwjBm5FrwthFEzuTZ91D33sRSB4ft9v
